Workbook

Sheet Precios
A1: Fecha | B1: S29E7 | C1: TMF27 | D1: TML27 | E1: T15E7 | F1: T31Y7 | G1: T31Y7 | H1: X29E7 | I1: TZXY7 | J1: S30N6 | K1: T30A7 | L1: T30J7 | M1: TZX27 | N1: TZXA7 | O1: X30N6
A2: 46072 | C2: 103 | E2: 121.45 | F2: 103.7 | G2: 1.037 | I2: 1.039 | J2: 1.0255 | K2: 1.096 | L2: 1.0525 | M2: 3.149 | N2: 0.995 | O2: 1.004
A3: 46073 | C3: 104.9 | E3: 121.8 | F3: 104.15 | G3: 1.0415 | I3: 1.0385 | J3: 1.0275 | K3: 1.1015 | L3: 1.055 | M3: 3.195 | N3: 0.99 | O3: 1.00525
A4: 46076 | C4: 104 | E4: 121.9 | F4: 103.5 | G4: 1.035 | I4: 1 | J4: 1.0294 | K4: 1.103 | L4: 1.052 | M4: 3.183 | N4: 1.033 | O4: 1.0085
A5: 46077 | C5: 103.5 | E5: 123.55 | F5: 105.15 | G5: 1.0515 | I5: 1.009 | J5: 1.03895 | K5: 1.116 | L5: 1.0615 | M5: 3.178 | N5: 1.005 | O5: 1.0115
A6: 46078 | C6: 104.9 | E6: 123.6 | F6: 105.5 | G6: 1.055 | J6: 1.041 | K6: 1.119 | L6: 1.0615 | M6: 3.1705 | N6: 1.005 | O6: 1.0115
A7: 46079 | C7: 103.5 | E7: 124.15 | F7: 106 | G7: 1.06 | I7: 1.026 | J7: 1.04201 | K7: 1.1255 | L7: 1.075 | M7: 3.204 | N7: 1.01 | O7: 1.017
A8: 46080 | C8: 104.9 | E8: 124.5 | F8: 106 | G8: 1.06 | I8: 1.029 | J8: 1.049 | K8: 1.1285 | L8: 1.104 | M8: 3.25 | N8: 1.04 | O8: 1.0245
A9: 46083 | C9: 107 | E9: 124.8 | F9: 106.75 | G9: 1.0675 | I9: 1.029 | J9: 1.0555 | K9: 1.1285 | L9: 1.091 | M9: 3.2555 | N9: 1.02 | O9: 1.024
A10: 46084 | C10: 106.8 | E10: 124.3 | F10: 106.7 | G10: 1.067 | I10: 1.029 | J10: 1.0585 | K10: 1.122 | L10: 1.084 | M10: 3.2325 | N10: 1.03 | O10: 1.027
A11: 46085 | C11: 106.8 | E11: 124.6 | F11: 106.75 | G11: 1.0675 | I11: 0.998 | J11: 1.0575 | K11: 1.125 | L11: 1.085 | M11: 3.249 | N11: 1.04 | O11: 1.03
A12: 46086 | C12: 105.2 | E12: 124.6 | F12: 106.5 | G12: 1.065 | I12: 1.039 | J12: 1.05236 | K12: 1.1245 | L12: 1.0775 | M12: 3.246 | N12: 1.0675 | O12: 1.032
A13: 46087 | C13: 105 | E13: 124.65 | F13: 106 | G13: 1.06 | I13: 1.0455 | J13: 1.048 | K13: 1.124 | L13: 1.075 | M13: 3.241 | O13: 1.035
A14: 46090 | C14: 104.55 | E14: 125 | F14: 105.75 | G14: 1.0575 | I14: 1.0395 | J14: 1.045 | K14: 1.125 | L14: 1.0745 | M14: 3.25 | N14: 1.0675 | O14: 1.0359
A15: 46091 | C15: 106.05 | E15: 125.5 | F15: 106.65 | G15: 1.0665 | I15: 1.01 | J15: 1.0494 | K15: 1.1295 | L15: 1.075 | M15: 3.25 | N15: 1.068 | O15: 1.0379
A16: 46092 | C16: 106.8 | E16: 126 | F16: 106.8 | G16: 1.068 | I16: 1.02 | J16: 1.05 | K16: 1.1355 | L16: 1.083 | M16: 3.254 | N16: 1.0675 | O16: 1.0385
A17: 46093 | C17: 106.2 | E17: 124.5 | F17: 106.45 | G17: 1.0645 | I17: 1.01 | J17: 1.0455 | K17: 1.1285 | L17: 1.0825 | M17: 3.2505 | N17: 1.016 | O17: 1.04099
A18: 46094 | C18: 107.95 | E18: 125.9 | F18: 106.55 | G18: 1.0655 | I18: 1.037 | J18: 1.059 | K18: 1.1355 | L18: 1.0875 | M18: 3.3 | N18: 1.038 | O18: 1.054
A19: 46097 | C19: 107.75 | E19: 127.15 | F19: 107.1 | G19: 1.071 | I19: 1.0485 | J19: 1.0609 | K19: 1.142 | L19: 1.087 | M19: 3.343 | N19: 1.048 | O19: 1.066
A20: 46098 | C20: 107.25 | E20: 127.4 | F20: 107.75 | G20: 1.0775 | I20: 1.045 | J20: 1.0617 | K20: 1.144 | L20: 1.095 | M20: 3.39 | N20: 1.0485 | O20: 1.0665
A21: 46099 | C21: 106.95 | E21: 127.6 | F21: 107.55 | G21: 1.0755 | I21: 1.05 | J21: 1.063 | K21: 1.1465 | L21: 1.098 | M21: 3.4045 | N21: 1.07 | O21: 1.0693
A22: 46100 | C22: 106.65 | E22: 128.1 | F22: 108.8 | G22: 1.088 | I22: 1.049 | J22: 1.0675 | K22: 1.1555 | L22: 1.1 | M22: 3.36 | N22: 1.069 | O22: 1.0665
A23: 46101 | C23: 107.5 | E23: 128.15 | F23: 109.2 | G23: 1.092 | I23: 1.04 | J23: 1.074 | K23: 1.1625 | L23: 1.105 | M23: 3.369 | N23: 1.06 | O23: 1.0725
A24: 46104 | C24: 108.15 | E24: 128.5 | F24: 109.8 | G24: 1.098 | I24: 1.05 | J24: 1.086 | K24: 1.167 | L24: 1.1195 | M24: 3.4215 | N24: 1.0695 | O24: 1.0795
A25: 46106 | C25: 106.2 | E25: 128.65 | F25: 110.1 | G25: 1.101 | I25: 1.065 | J25: 1.07599 | K25: 1.167 | L25: 1.109 | M25: 3.41 | N25: 1.0675 | O25: 1.0745
... A88: 46202 | C88: 116.2 | E88: 142.25 | F88: 122.85 | G88: 1.2285 | I88: 1.1645 | J88: 1.18555 | K88: 1.29839 | L88: 1.2375 | M88: 3.771 | N88: 1.175 | O88: 1.1877
A89: 46203 | C89: 116.5 | D89: 101.7 | E89: 142.84 | F89: 123.06 | G89: 1.2306 | I89: 1.163 | J89: 1.189 | K89: 1.30189 | L89: 1.25645 | M89: 3.777 | N89: 1.1815 | O89: 1.189
A90: 46204 | C90: 116.15 | D90: 101.6 | E90: 143 | F90: 123.7 | G90: 1.237 | I90: 1.163 | J90: 1.188 | K90: 1.3029 | L90: 1.248 | M90: 3.77 | N90: 1.1785 | O90: 1.189
A91: 46205 | C91: 116.2 | D91: 101.7 | E91: 143.249 | F91: 123.45 | G91: 1.2345 | I91: 1.163 | J91: 1.188 | K91: 1.3055 | L91: 1.252 | M91: 3.779 | N91: 1.1875 | O91: 1.1907
A92: 46206 | C92: 116.55 | D92: 102.3 | E92: 144 | F92: 123.61 | G92: 1.2361 | I92: 1.165 | J92: 1.1905 | K92: 1.31 | L92: 1.256 | M92: 3.8045 | N92: 1.1845 | O92: 1.19412
A93: 46209 | C93: 116.6 | D93: 102.5 | E93: 143.2 | F93: 123.999 | G93: 1.23999 | I93: 1.1615 | J93: 1.191 | K93: 1.312 | L93: 1.259 | M93: 3.828 | N93: 1.1885 | O93: 1.19675
A94: 46210 | C94: 116.65 | D94: 102.8 | E94: 144.2 | F94: 124.5 | G94: 1.245 | I94: 1.169 | J94: 1.1911 | K94: 1.3131 | L94: 1.265 | M94: 3.833 | N94: 1.188 | O94: 1.196
A95: 46211 | C95: 117.05 | D95: 102.9 | E95: 144 | F95: 124.701 | G95: 1.24701 | I95: 1.169 | J95: 1.19548 | K95: 1.315 | L95: 1.2675 | M95: 3.84 | N95: 1.18 | O95: 1.1995
A96: 46213 | C96: 118.95 | D96: 104 | E96: 144.4 | F96: 126 | G96: 1.26 | I96: 1.179 | J96: 1.1985 | K96: 1.3155 | L96: 1.275 | M96: 3.838 | O96: 1.20112
A97: 46216 | C97: 117 | D97: 102.9 | E97: 144.32 | F97: 124.5 | G97: 1.245 | I97: 1.168 | J97: 1.1939 | K97: 1.316 | L97: 1.2681 | M97: 3.838 | N97: 1.19 | O97: 1.199
A98: 46217 | C98: 117.1 | D98: 103 | E98: 144.05 | F98: 124.439 | G98: 1.24439 | I98: 1.168 | J98: 1.19262 | K98: 1.3155 | L98: 1.26899 | M98: 3.8445 | N98: 1.1895 | O98: 1.1995
A99: 46218 | C99: 117.1 | D99: 103.75 | E99: 144.35 | F99: 124.45 | G99: 1.2445 | I99: 1.172 | J99: 1.197 | K99: 1.317 | L99: 1.275 | M99: 3.8475 | N99: 1.191 | O99: 1.19871
A100: 46219 | C100: 116.95 | D100: 103.3 | E100: 143.8 | F100: 124.32 | G100: 1.2432 | I100: 1.168 | J100: 1.19263 | K100: 1.31499 | L100: 1.27 | M100: 3.845 | N100: 1.1905 | O100: 1.2014
A101: 46220 | C101: 117.2 | D101: 103.1 | E101: 144.34 | F101: 124.45 | G101: 1.2445 | I101: 1.165 | J101: 1.1964 | K101: 1.3172 | L101: 1.2619 | M101: 3.845 | N101: 1.1945 | O101: 1.2036
A102: 46223 | C102: 117.2 | D102: 103.15 | E102: 144.2 | F102: 124.37 | G102: 1.2437 | I102: 1.171 | J102: 1.19679 | K102: 1.316 | L102: 1.26 | M102: 3.8525 | N102: 1.1905 | O102: 1.207
...

Sheet Tamar
A1: Fecha | B1: Tamar
A2: 45659 | B2: 34.3125
A3: 45660 | B3: 34.5
A4: 45663 | B4: 34.75
A5: 45664 | B5: 34.8125
A6: 45665 | B6: 33.9375
A7: 45666 | B7: 34.1875
A8: 45667 | B8: 34.1875
A9: 45670 | B9: 34.25
A10: 45671 | B10: 34.5625
A11: 45672 | B11: 32.875
A12: 45673 | B12: 33.1875
A13: 45674 | B13: 32.5625
... A255: 46042 | B255: 36.6875
A256: 46043 | B256: 36.9375 | C256: ,
A257: 46044 | B257: 38.0625
A258: 46045 | B258: 37.8125
A259: 46048 | B259: 35.625
A260: 46049 | B260: 34.5
A261: 46050 | B261: 32.625
A262: 46051 | B262: 31.75
A263: 46052 | B263: 32.9375 | C263: ,
A264: 46055 | B264: 32.6875
A265: 46056 | B265: 34
A266: 46057 | B266: 32.5625
A267: 46058 | B267: 32.1875
A268: 46059 | B268: 31.8125
A269: 46062 | B269: 31.1875
A270: 46063 | B270: 31.375
A271: 46064 | B271: 31.5625
A272: 46065 | B272: 32.375
A273: 46066 | B273: 33.4375
A274: 46071 | B274: 33.6875
A275: 46072 | B275: 34.625
... A419: 46288 | B419: 23.6875
A420: =+WORKDAY(A419,1,Feriados!$A$2:$A$38) -> 46289 | B420: =+IFERROR(VLOOKUP(A420,[3]Variables!$M:$N,2,0),0) -> 23.75
A421: =+WORKDAY(A420,1,Feriados!$A$2:$A$38) -> 46290 | B421: =+IFERROR(VLOOKUP(A421,[3]Variables!$M:$N,2,0),0) -> 23.625
A422: =+WORKDAY(A421,1,Feriados!$A$2:$A$38) -> 46293 | B422: =+IFERROR(VLOOKUP(A422,[3]Variables!$M:$N,2,0),0) -> 23.4375
A423: =+WORKDAY(A422,1,Feriados!$A$2:$A$38) -> 46294 | B423: =+IFERROR(VLOOKUP(A423,[3]Variables!$M:$N,2,0),0) -> 24.3125
A424: =+WORKDAY(A423,1,Feriados!$A$2:$A$38) -> 46295 | B424: =+IFERROR(VLOOKUP(A424,[3]Variables!$M:$N,2,0),0) -> 24.125
...

Sheet CER
A1: Fecha | B1: CER
A2: 45659 | B2: 516.30554
A3: 45660 | B3: 516.70069
A4: 45663 | B4: 517.88796
A5: 45664 | B5: 518.28432
A6: 45665 | B6: 518.68098
A7: 45666 | B7: 519.07795
A8: 45667 | B8: 519.47522
A9: 45670 | B9: 520.66886
A10: 45671 | B10: 521.06736
A11: 45672 | B11: 521.46615
A12: 45673 | B12: 521.9145
A13: 45674 | B13: 522.36323
... A419: 46288 | B419: 843.96091
A420: =+WORKDAY(A419,1,[5]Feriados!$A$2:$A$38) -> 46289 | B420: 844.43527
A421: =+WORKDAY(A420,1,[5]Feriados!$A$2:$A$38) -> 46290 | B421: 844.9099
A422: =+WORKDAY(A421,1,[5]Feriados!$A$2:$A$38) -> 46293 | B422: 846.33537
A423: =+WORKDAY(A422,1,[5]Feriados!$A$2:$A$38) -> 46294 | B423: 846.81107
A424: =+WORKDAY(A423,1,[5]Feriados!$A$2:$A$38) -> 46295 | B424: 847.28703
A425: =+WORKDAY(A424,1,[5]Feriados!$A$2:$A$38) -> 46296 | B425: =+IFERROR(VLOOKUP(A425,[3]Variables!$P:$Q,2,0),B424) -> 847.76325
A426: =+WORKDAY(A425,1,[5]Feriados!$A$2:$A$38) -> 46297 | B426: =+IFERROR(VLOOKUP(A426,[3]Variables!$P:$Q,2,0),B425) -> 848.23975
A427: =+WORKDAY(A426,1,[5]Feriados!$A$2:$A$38) -> 46300 | B427: =+IFERROR(VLOOKUP(A427,[3]Variables!$P:$Q,2,0),B426) -> 849.67084
A428: =+WORKDAY(A427,1,[5]Feriados!$A$2:$A$38) -> 46301 | B428: =+IFERROR(VLOOKUP(A428,[3]Variables!$P:$Q,2,0),B427) -> 850.14841
A429: =+WORKDAY(A428,1,[5]Feriados!$A$2:$A$38) -> 46302 | B429: =+IFERROR(VLOOKUP(A429,[3]Variables!$P:$Q,2,0),B428) -> 850.62625
A430: =+WORKDAY(A429,1,[5]Feriados!$A$2:$A$38) -> 46303 | B430: =+IFERROR(VLOOKUP(A430,[3]Variables!$P:$Q,2,0),B429) -> 851.10435
A431: =+WORKDAY(A430,1,[5]Feriados!$A$2:$A$38) -> 46304 | B431: =+IFERROR(VLOOKUP(A431,[3]Variables!$P:$Q,2,0),B430) -> 851.58272
A432: =+WORKDAY(A431,1,[5]Feriados!$A$2:$A$38) -> 46308 | B432: =+IFERROR(VLOOKUP(A432,[3]Variables!$P:$Q,2,0),B431) -> 853.49891
A433: =+WORKDAY(A432,1,[5]Feriados!$A$2:$A$38) -> 46309 | B433: =+IFERROR(VLOOKUP(A433,[3]Variables!$P:$Q,2,0),B432) -> 853.97863
A434: =+WORKDAY(A433,1,[5]Feriados!$A$2:$A$38) -> 46310 | B434: =+IFERROR(VLOOKUP(A434,[3]Variables!$P:$Q,2,0),B433) -> 854.45862
A435: =+WORKDAY(A434,1,[5]Feriados!$A$2:$A$38) -> 46311 | B435: =+IFERROR(VLOOKUP(A435,[3]Variables!$P:$Q,2,0),B434) -> 854.97756
A436: =+WORKDAY(A435,1,Feriados!$A$2:$A$38) -> 46314 | B436: =+IFERROR(VLOOKUP(A436,[3]Variables!$P:$Q,2,0),B435) -> 856.53629
A437: =+WORKDAY(A436,1,Feriados!$A$2:$A$38) -> 46315 | B437: =+IFERROR(VLOOKUP(A437,[3]Variables!$P:$Q,2,0),B436) -> 857.05649
A438: =+WORKDAY(A437,1,Feriados!$A$2:$A$38) -> 46316 | B438: =+IFERROR(VLOOKUP(A438,[3]Variables!$P:$Q,2,0),B437) -> 857.57702
A439: =+WORKDAY(A438,1,Feriados!$A$2:$A$38) -> 46317 | B439: =+IFERROR(VLOOKUP(A439,[3]Variables!$P:$Q,2,0),B438) -> 858.09786
A440: =+WORKDAY(A439,1,Feriados!$A$2:$A$38) -> 46318 | B440: =+IFERROR(VLOOKUP(A440,[3]Variables!$P:$Q,2,0),B439) -> 858.61901
A441: =+WORKDAY(A440,1,Feriados!$A$2:$A$38) -> 46321 | B441: =+IFERROR(VLOOKUP(A441,[3]Variables!$P:$Q,2,0),B440) -> 860.18438
A442: =+WORKDAY(A441,1,Feriados!$A$2:$A$38) -> 46322 | B442: =+IFERROR(VLOOKUP(A442,[3]Variables!$P:$Q,2,0),B441) -> 860.7068
A443: =+WORKDAY(A442,1,Feriados!$A$2:$A$38) -> 46323 | B443: =+IFERROR(VLOOKUP(A443,[3]Variables!$P:$Q,2,0),B442) -> 861.22954
A444: =+WORKDAY(A443,1,Feriados!$A$2:$A$38) -> 46324 | B444: =+IFERROR(VLOOKUP(A444,[3]Variables!$P:$Q,2,0),B443) -> 861.7526
A445: =+WORKDAY(A444,1,Feriados!$A$2:$A$38) -> 46325 | B445: =+IFERROR(VLOOKUP(A445,[3]Variables!$P:$Q,2,0),B444) -> 862.27597
...

Sheet Feriados
A1: Feriados
A2: =+[4]Hoja1!$B31 -> 46167
A3: =+[4]Hoja1!$B32 -> 46188
A4: =+[4]Hoja1!$B33 -> 46212
A5: =+[4]Hoja1!$B34 -> 46213
A6: =+[4]Hoja1!$B35 -> 46251
A7: =+[4]Hoja1!$B36 -> 46307
A8: =+[4]Hoja1!$B37 -> 46332
A9: =+[4]Hoja1!$B38 -> 46335
A10: =+[4]Hoja1!$B39 -> 46336
A11: =+[4]Hoja1!$B40 -> 46349
A12: =+[4]Hoja1!$B41 -> 46363
A13: =+[4]Hoja1!$B42 -> 46364
A14: =+[4]Hoja1!$B43 -> 46381

Sheet Lecaps
A1: Ticker | B1: Emisión | C1: Vencimiento | D1: Tasa
A2: T15E7 | B2: 45688 | C2: 46402 | D2: 0.0205
A3: S29E7 | B3: 46265 | C3: 46416 | D3: 0.0219
A4: T31Y7 | B4: 46006 | C4: 46538 | D4: 0.024

Sheet Letam
A1: Ticker | B1: Emisión | C1: Vencimiento | D1: Tasa
A2: TMF27 | B2: 46066 | C2: 46444 | D2: 0.065
A3: TML27 | B3: 46203 | C3: 46598 | D3: 0.054

Sheet LECER
A1: Ticker | B1: Emisión | C1: Vencimiento | D1: Tasa | E1: CER inicial
A2: X29E7 | B2: 46248 | C2: 46416 | D2: 0 | E2: 815.4345
A3: TZXY7 | B3: 46006 | C3: 46538 | D3: 0 | E3: 659.6789
A4: TZX27 | B4: 45323 | C4: 46568 | D4: 0 | E4: 200.388
A5: TZXA7 | B5: 45989 | C5: 46507 | D5: 0 | E5: 651.8981
A6: X30N6 | B6: 46006 | C6: 46356 | D6: 0 | E6: 659.6789
